Workbook

Sheet Budget Calculator
A1: Rural Connectivity Budget Tool | J1: to put on https://bridgedesignv3.streamlit.app/Bridge_Price_Estimation
A2: This tool helps transport planners, financiers, and policymakers explore how a small share of a larger transport project budget (like a large corridor investment) could fund essential Rural Networked Transport Infrastructure (RNTI) — the trail bridges, footpaths, low-water crossings, ancillary safety, and active mobility components that connect rural communities to primary networks. RNTI is defined and detailed in Segerberg & Noriega (2026), Advancing Inclusive, Multimodal, Climate-Resilient Planning for Rural Networked Transport Infrastructure. The calculator is designed to raise awareness of how modest, evidence-based RNTI add-ons — typically 1% to 10% of a transport project budget — can meaningfully improve resilience, market access, and equity outcomes for the roughly 3 billion people living in rural/semi-rural areas worldwide. To use the tool, enter your total project budget, the percentage you want to allocate to RNTI, and an optional maintenance reserve. Then enter quantities next to any of the RNTI components you would like to fund. The calculator returns total estimated costs, a remaining budget, and a summary of your allocation. Unit cost ranges are approximations using blended averages from available, verifiable sources. This version is an illustrative, back-of-the-envelope tool using high-level cost estimates.
A4: This is an initial version of the Rural Connectivity Budget Tool. Estimated budgets are approximations based on blended averages of publicly available cost data and may not reflect local market conditions, terrain, labor rates, or design specifications in any specific country or project. Fika will integrate more nuanced cost approximations and social and climate impact information in future iterations of this tool. Suggestions, corrections, additional cost data, and inquiries are warmly welcomed — contact our research team here.
B7: SECTION 1: TRANSPORT PROJECT INPUTS
B8: [Info for Cameron/Youdahe Only -- the editable fields in the calculator tool should be the ones in yellow below]
B9: Project Name / Description
B10: Country / Region
B12: Total Transport Project Budget (USD) | C12: 0
B13: % Allocated to RNTI / Rural Access | C13: 0
B14: RNTI Budget Available | C14: =C12*C13 -> 0
B16: Maintenance Reserve (%) | C16: 0 | D16: Recommended: 5-15% of RNTI budget
B17: Maintenance Reserve Amount | C17: =C14*C16 -> 0
B18: Capital Budget for Infrastructure | C18: =C14-C17 -> 0
B21: SECTION 2: INFRASTRUCTURE MIX — Enter desired quantities in column G
B22: [Info for Cameron/Youdahe Only -- Unit costs link directly from the 'Source Data' sheet blended averages. Brooke and I are adjusting]
A23: # | B23: Infrastructure Type | C23: Unit | D23: Min Unit Cost | E23: Max Unit Cost | F23: Mid Unit Cost | G23: Qty | H23: Total Cost Estimate (Mid) | I23: Total Cost Estimate Range
B24: ORDER 3 TERTIARY LINKS
A25: 1 | B25: Low-Volume Rural Road (basic earth road) | C25: km | D25: =IF('Source Data - In Progress'!C15="","",'Source Data - In Progress'!C15) -> 16213 | E25: =IF('Source Data - In Progress'!D15="","",'Source Data - In Progress'!D15) -> 25099 | F25: =IF('Source Data - In Progress'!E15="","",'Source Data - In Progress'!E15) -> 20656 | G25: 0 | H25: =IFERROR(F25*G25,"") -> 0 | I25: =IFERROR(IF(G25=0,"-",TEXT(D25*G25,"$#,##0")&" - "&TEXT(E25*G25,"$#,##0")),"") -> -
A26: 2 | B26: Low-Volume Rural Road (improved surface) | C26: km | D26: =IF('Source Data - In Progress'!C27="","",'Source Data - In Progress'!C27) -> 88073 | E26: =IF('Source Data - In Progress'!D27="","",'Source Data - In Progress'!D27) -> 156410 | F26: =IF('Source Data - In Progress'!E27="","",'Source Data - In Progress'!E27) -> 122241 | G26: 0 | H26: =IFERROR(F26*G26,"") -> 0 | I26: =IFERROR(IF(G26=0,"-",TEXT(D26*G26,"$#,##0")&" - "&TEXT(E26*G26,"$#,##0")),"") -> -
A27: 3 | B27: Rural Road Bridge (vehicular, simple) | C27: linear foot | D27: =IF('Source Data - In Progress'!C34="","",'Source Data - In Progress'!C34) -> 3048 | E27: =IF('Source Data - In Progress'!D34="","",'Source Data - In Progress'!D34) -> 3981 | F27: =IF('Source Data - In Progress'!E34="","",'Source Data - In Progress'!E34) -> 3515 | G27: 0 | H27: =IFERROR(F27*G27,"") -> 0 | I27: =IFERROR(IF(G27=0,"-",TEXT(D27*G27,"$#,##0")&" - "&TEXT(E27*G27,"$#,##0")),"") -> -
A28: 4 | B28: Fixed Culvert Crossing | C28: linear foot | D28: =IF('Source Data - In Progress'!C43="","",'Source Data - In Progress'!C43) -> 368 | E28: =IF('Source Data - In Progress'!D43="","",'Source Data - In Progress'!D43) -> 545 | F28: =IF('Source Data - In Progress'!E43="","",'Source Data - In Progress'!E43) -> 457 | G28: 0 | H28: =IFERROR(F28*G28,"") -> 0 | I28: =IFERROR(IF(G28=0,"-",TEXT(D28*G28,"$#,##0")&" - "&TEXT(E28*G28,"$#,##0")),"") -> -
A29: 5 | B29: Seasonal Causeway / Low-Water Crossing | C29: crossings | D29: =IF('Source Data - In Progress'!C49="","",'Source Data - In Progress'!C49) -> 20250 | E29: =IF('Source Data - In Progress'!D49="","",'Source Data - In Progress'!D49) -> 26250 | F29: =IF('Source Data - In Progress'!E49="","",'Source Data - In Progress'!E49) -> 23250 | G29: 0 | H29: =IFERROR(F29*G29,"") -> 0 | I29: =IFERROR(IF(G29=0,"-",TEXT(D29*G29,"$#,##0")&" - "&TEXT(E29*G29,"$#,##0")),"") -> -
A30: 6 | B30: Temporary / Emergency Bridge | C30: bridges | D30: =IF('Source Data - In Progress'!C55="","",'Source Data - In Progress'!C55) -> 70000 | E30: =IF('Source Data - In Progress'!D55="","",'Source Data - In Progress'!D55) -> 225000 | F30: =IF('Source Data - In Progress'!E55="","",'Source Data - In Progress'!E55) -> 147500 | G30: 0 | H30: =IFERROR(F30*G30,"") -> 0 | I30: =IFERROR(IF(G30=0,"-",TEXT(D30*G30,"$#,##0")&" - "&TEXT(E30*G30,"$#,##0")),"") -> -
A31: 7 | B31: Stone Arch Bridge | C31: bridges | D31: ='Source Data - In Progress'!C64 -> 46573 | E31: ='Source Data - In Progress'!D64 -> 46573 | F31: ='Source Data - In Progress'!E64 -> 46573 | G31: 0 | H31: =IFERROR(F31*G31,"") -> 0 | I31: =IFERROR(IF(G31=0,"-",TEXT(D31*G31,"$#,##0")&" - "&TEXT(E31*G31,"$#,##0")),"") -> -
B32: SUB-TERTIARY LINKS
A33: 8 | B33: Footpath Construction | C33: km | D33: =IF('Source Data - In Progress'!C75="","",'Source Data - In Progress'!C75) -> 89181 | E33: =IF('Source Data - In Progress'!D75="","",'Source Data - In Progress'!D75) -> 89631 | F33: =IF('Source Data - In Progress'!E75="","",'Source Data - In Progress'!E75) -> 89406 | G33: 0 | H33: =IFERROR(F33*G33,"") -> 0 | I33: =IFERROR(IF(G33=0,"-",TEXT(D33*G33,"$#,##0")&" - "&TEXT(E33*G33,"$#,##0")),"") -> -
A34: 9 | B34: Trail / Track Improvement (IMT-suitable) | C34: km | D34: =IF('Source Data - In Progress'!C82="","",'Source Data - In Progress'!C82) -> 6376 | E34: =IF('Source Data - In Progress'!D82="","",'Source Data - In Progress'!D82) -> 7709 | F34: =IF('Source Data - In Progress'!E82="","",'Source Data - In Progress'!E82) -> 7042 | G34: 0 | H34: =IFERROR(F34*G34,"") -> 0 | I34: =IFERROR(IF(G34=0,"-",TEXT(D34*G34,"$#,##0")&" - "&TEXT(E34*G34,"$#,##0")),"") -> -
A35: 10 | B35: Pedestrian Trail Bridge | C35: linear foot | D35: =IF('Source Data - In Progress'!C89="","",'Source Data - In Progress'!C89) -> 1113 | E35: =IF('Source Data - In Progress'!D89="","",'Source Data - In Progress'!D89) -> 2219 | F35: =IF('Source Data - In Progress'!E89="","",'Source Data - In Progress'!E89) -> 1666 | G35: 0 | H35: =IFERROR(F35*G35,"") -> 0 | I35: =IFERROR(IF(G35=0,"-",TEXT(D35*G35,"$#,##0")&" - "&TEXT(E35*G35,"$#,##0")),"") -> -
A36: 11 | B36: Improvised / Community Bridge (log/plank/bamboo) | C36: linear foot | D36: =IF('Source Data - In Progress'!C94="","",'Source Data - In Progress'!C94) -> 300 | E36: =IF('Source Data - In Progress'!D94="","",'Source Data - In Progress'!D94) -> 600 | F36: =IF('Source Data - In Progress'!E94="","",'Source Data - In Progress'!E94) -> 450 | G36: 0 | H36: =IFERROR(F36*G36,"") -> 0 | I36: =IFERROR(IF(G36=0,"-",TEXT(D36*G36,"$#,##0")&" - "&TEXT(E36*G36,"$#,##0")),"") -> -
A37: 12 | B37: Steel I-Beam Span Bridge | C37: linear foot | D37: =IF('Source Data - In Progress'!C100="","",'Source Data - In Progress'!C100) -> 450 | E37: =IF('Source Data - In Progress'!D100="","",'Source Data - In Progress'!D100) -> 1800 | F37: =IF('Source Data - In Progress'!E100="","",'Source Data - In Progress'!E100) -> 1125 | G37: 0 | H37: =IFERROR(F37*G37,"") -> 0 | I37: =IFERROR(IF(G37=0,"-",TEXT(D37*G37,"$#,##0")&" - "&TEXT(E37*G37,"$#,##0")),"") -> -
A38: 13 | B38: Ferry / Non-Fixed Water Crossing (setup) | C38: crossings | D38: =IF('Source Data - In Progress'!C109="","",'Source Data - In Progress'!C109) -> 6600 | E38: =IF('Source Data - In Progress'!D109="","",'Source Data - In Progress'!D109) -> 28900 | F38: =IF('Source Data - In Progress'!E109="","",'Source Data - In Progress'!E109) -> 21050 | G38: 0 | H38: =IFERROR(F38*G38,"") -> 0 | I38: =IFERROR(IF(G38=0,"-",TEXT(D38*G38,"$#,##0")&" - "&TEXT(E38*G38,"$#,##0")),"") -> -
A39: 14 | B39: Hillside Ladder / Stairway | C39: per meter | D39: =IF('Source Data - In Progress'!C115="","",'Source Data - In Progress'!C115) -> 138 | E39: =IF('Source Data - In Progress'!D115="","",'Source Data - In Progress'!D115) -> 138 | F39: =IF('Source Data - In Progress'!E115="","",'Source Data - In Progress'!E115) -> 138 | G39: 0 | H39: =IFERROR(F39*G39,"") -> 0 | I39: =IFERROR(IF(G39=0,"-",TEXT(D39*G39,"$#,##0")&" - "&TEXT(E39*G39,"$#,##0")),"") -> -
A40: 15 | B40: Ropeway / Cableway | C40: installations | D40: =IF('Source Data - In Progress'!C121="","",'Source Data - In Progress'!C121) -> 8431 | E40: =IF('Source Data - In Progress'!D121="","",'Source Data - In Progress'!D121) -> 11000 | F40: =IF('Source Data - In Progress'!E121="","",'Source Data - In Progress'!E121) -> 9716 | G40: 0 | H40: =IFERROR(F40*G40,"") -> 0 | I40: =IFERROR(IF(G40=0,"-",TEXT(D40*G40,"$#,##0")&" - "&TEXT(E40*G40,"$#,##0")),"") -> -
B41: ANCILLARY & SAFETY INFRASTRUCTURE
A42: 16 | B42: Drainage at Crossings | C42: linear foot | D42: =IF('Source Data - In Progress'!C130="","",'Source Data - In Progress'!C130) -> 20 | E42: =IF('Source Data - In Progress'!D130="","",'Source Data - In Progress'!D130) -> 34 | F42: =IF('Source Data - In Progress'!E130="","",'Source Data - In Progress'!E130) -> 27 | G42: 0 | H42: =IFERROR(F42*G42,"") -> 0 | I42: =IFERROR(IF(G42=0,"-",TEXT(D42*G42,"$#,##0")&" - "&TEXT(E42*G42,"$#,##0")),"") -> -
A43: 17 | B43: Basic Signage / Wayfinding | C43: signs | D43: =IF('Source Data - In Progress'!C137="","",'Source Data - In Progress'!C137) -> 127 | E43: =IF('Source Data - In Progress'!D137="","",'Source Data - In Progress'!D137) -> 365 | F43: =IF('Source Data - In Progress'!E137="","",'Source Data - In Progress'!E137) -> 246 | G43: 0 | H43: =IFERROR(F43*G43,"") -> 0 | I43: =IFERROR(IF(G43=0,"-",TEXT(D43*G43,"$#,##0")&" - "&TEXT(E43*G43,"$#,##0")),"") -> -
A44: 18 | B44: Lighting (solar) | C44: units | D44: =IF('Source Data - In Progress'!C143="","",'Source Data - In Progress'!C143) -> 700 | E44: =IF('Source Data - In Progress'!D143="","",'Source Data - In Progress'!D143) -> 2150 | F44: =IF('Source Data - In Progress'!E143="","",'Source Data - In Progress'!E143) -> 1425 | G44: 0 | H44: =IFERROR(F44*G44,"") -> 0 | I44: =IFERROR(IF(G44=0,"-",TEXT(D44*G44,"$#,##0")&" - "&TEXT(E44*G44,"$#,##0")),"") -> -
A45: 19 | B45: Rest Stop / Waiting Shelter | C45: shelters | D45: =IF('Source Data - In Progress'!C148="","",'Source Data - In Progress'!C148) -> 33681 | E45: =IF('Source Data - In Progress'!D148="","",'Source Data - In Progress'!D148) -> 33681 | F45: =IF('Source Data - In Progress'!E148="","",'Source Data - In Progress'!E148) -> 33681 | G45: 0 | H45: =IFERROR(F45*G45,"") -> 0 | I45: =IFERROR(IF(G45=0,"-",TEXT(D45*G45,"$#,##0")&" - "&TEXT(E45*G45,"$#,##0")),"") -> -
A46: 20 | B46: ICT / Connectivity Point (Wi-Fi/mesh) | C46: installations | D46: ='Source Data - In Progress'!C156 -> 767 | E46: ='Source Data - In Progress'!D156 -> 2900 | F46: ='Source Data - In Progress'!E156 -> 3000 | G46: 0 | H46: =IFERROR(F46*G46,"") -> 0 | I46: =IFERROR(IF(G46=0,"-",TEXT(D46*G46,"$#,##0")&" - "&TEXT(E46*G46,"$#,##0")),"") -> -
A47: 21 | B47: Charging Point (solar) | C47: stations | D47: =IF('Source Data - In Progress'!C162="","",'Source Data - In Progress'!C162) -> 900 | E47: =IF('Source Data - In Progress'!D162="","",'Source Data - In Progress'!D162) -> 3250 | F47: =IF('Source Data - In Progress'!E162="","",'Source Data - In Progress'!E162) -> 2075 | G47: 0 | H47: =IFERROR(F47*G47,"") -> 0 | I47: =IFERROR(IF(G47=0,"-",TEXT(D47*G47,"$#,##0")&" - "&TEXT(E47*G47,"$#,##0")),"") -> -
...

Sheet Source Data - In Progress
A1: RNTI COST SOURCE DATA — Verifiable Sources with Integrated Blended Averages
A2: Each item section lists individual source data points and ends with a BLENDED AVERAGE row (Min / Max / Mid) computed from those points. Items with no verifiable source are intentionally blank for further research. Click source citations to open the original document.
A4: ORDER 3 TERTIARY LINKS
A5: Low-Volume Rural Road (earth) (per km)
A6: # | B6: Geography / Context | C6: Low Est. (USD) | D6: High Est. (USD) | E6: Source Mid | F6: Source Name | G6: Full Citation | H6: Year
A7: 1 | B7: Africa (AfDB 2014 — regraveling of unpaved roads, small projects <100 lane km, Q1-Q3) | C7: 8100 | D7: 10500 | E7: =IFERROR(ROUND((C7+D7)/2,0),"") -> 9300 | F7: AfDB Study on Road Infrastructure Costs 2014 | G7: Source: African Development Bank, Study on Road Infrastructure Costs — Analysis of Unit Costs and Cost Overruns of Road Infrastructure Projects in Africa, May 2014, Table 4-8 (regraveling projects <100 lane km, quartile range) | H7: 2014
A8: 2 | B8: Africa (AfDB 2014 — regraveling of unpaved roads, large projects >=100 lane km, Q1-Q3) | C8: 9600 | D8: 12800 | E8: =IFERROR(ROUND((C8+D8)/2,0),"") -> 11200 | F8: AfDB Study on Road Infrastructure Costs 2014 | G8: Source: AfDB 2014 Study, Table 4-8, regraveling projects >=100 lane km quartile range | H8: 2014
A9: 3 | B9: Global rural (WB Technical Paper 496 — typical basic access road, 2001 USD) | C9: 5000 | D9: 5000 | E9: =IFERROR(ROUND((C9+D9)/2,0),"") -> 5000 | F9: World Bank Technical Paper 496 (2001) | G9: Source: World Bank, Technical Paper No. 496, Design and Appraisal of Rural Transport Infrastructure — Ensuring Basic Access for Rural Communities, 2001, p.20 (typical $5,000/km basic access road) | H9: 2001
A10: 4 | B10: India (WB TP 496 — formation & gravel single-lane rural road, financial cost, 2001 USD) | C10: 5000 | D10: 5000 | E10: =IFERROR(ROUND((C10+D10)/2,0),"") -> 5000 | F10: World Bank Technical Paper 496 (2001) | G10: Source: World Bank TP 496, Table E.1.3, Warangal district rural road paving project, formation + gravel financial capital cost | H10: 2001
A11: 5 | B11: Earth-road construction in mountainous areas: $10,000 to 50,000/km | C11: 10000 | D11: 50000 | E11: =IFERROR(ROUND((C11+D11)/2,0),"") -> 30000 | F11: https://www.ilo.org/sites/default/files/wcmsp5/groups/public/@ed_emp/@emp_policy/@invest/documents/instructionalmaterial/wcms_asist_8494.pdf
A12: 6 | B12: Uganda (unsurfaced roads) | C12: 15000 | D12: 15000 | E12: 15000 | F12: https://assets.publishing.service.gov.uk/media/57a08bd7e5274a27b2000dc3/TI_UP_HD_Feb2007_Cost_of_Roads_in_Africa.pdf
A13: 7 | B13: General global estimate from research | C13: 8000 | D13: 10000 | E13: =IFERROR(ROUND((C13+D13)/2,0),"") -> 9000 | F13: https://assets.publishing.service.gov.uk/media/57a08bd7e5274a27b2000dc3/TI_UP_HD_Feb2007_Cost_of_Roads_in_Africa.pdf
B14: [Rwanda numbers] | C14: 69000 | D14: 92495 | E14: =IFERROR(ROUND((C14+D14)/2,0),"") -> 80748 | F14: https://blogs.worldbank.org/en/nasikiliza/road-to-prosperity-how-feeder-roads-are-creating-jobs-and-transforming-lives-in-rural-rwanda-afe-0425 | H14: 2025
B15: BLENDED AVERAGE (Min / Max / Mid) | C15: =IFERROR(ROUND(AVERAGE(C7:C14),0),"") -> 16213 | D15: =IFERROR(ROUND(AVERAGE(D7:D14),0),"") -> 25099 | E15: =IFERROR(ROUND(AVERAGE(E7:E14),0),"") -> 20656
A17: Low-Volume Rural Road (improved surface) (per km)
A18: # | B18: Geography / Context | C18: Low Est. (USD) | D18: High Est. (USD) | E18: Source Mid | F18: Source Name | G18: Full Citation | H18: Year
A19: 1 | B19: Africa (AfDB 2014 — construction/upgrade of paved roads, small projects <100 lane km, Q1-Q3) | C19: 166300 | D19: 425400 | E19: =IFERROR(ROUND((C19+D19)/2,0),"") -> 295850 | F19: AfDB Study on Road Infrastructure Costs 2014 | G19: Source: AfDB 2014 Study, Table 4-5, construction/upgrading paved road projects <100 lane km, Q1-Q3 range | H19: 2014
A20: 2 | B20: Africa (AfDB 2014 — rehabilitation of paved roads, small projects <100 lane km, Q1-Q3) | C20: 109800 | D20: 290000 | E20: =IFERROR(ROUND((C20+D20)/2,0),"") -> 199900 | F20: AfDB Study on Road Infrastructure Costs 2014 | G20: Source: AfDB 2014 Study, Table 4-6, rehabilitation paved road projects <100 lane km, Q1-Q3 range | H20: 2014
A21: 3 | B21: Ghana (MCC Compact — Feeder Road Activity, 357 km for $71 M) | C21: 198880 | D21: 198880 | E21: =IFERROR(ROUND((C21+D21)/2,0),"") -> 198880 | F21: MCC Ghana Transportation Final Evaluation Brief 2020 | G21: Source: Millennium Challenge Corporation, Improving Roads to Reduce Transportation Costs in Ghana, Final Evaluation Brief, September 2020 ($71 M / 357 km rehabilitated feeder roads) | H21: 2020
A22: 4 | B22: India (WB TP 496 — surface treatment 6.5m wide, 2001 USD) | C22: 125000 | D22: 125000 | E22: =IFERROR(ROUND((C22+D22)/2,0),"") -> 125000 | F22: World Bank Technical Paper 496 (2001) | G22: Source: World Bank TP 496, Appendix F, Example 1 (surface treatment paving option, 6.5 m wide) | H22: 2001
A23: 5 | B23: India (WB TP 496 — concrete block 4.0 m / 6.5 m wide, 2001 USD) | C23: 48000 | D23: 78000 | E23: =IFERROR(ROUND((C23+D23)/2,0),"") -> 63000 | F23: World Bank Technical Paper 496 (2001) | G23: Source: World Bank TP 496, Appendix F, Example 1 (concrete block paving, 4.0 m and 6.5 m widths) | H23: 2001
A24: 6 | B24: India (WB TP 496 — India standard full rural road, 2001 USD) | C24: 40000 | D24: 40000 | E24: =IFERROR(ROUND((C24+D24)/2,0),"") -> 40000 | F24: World Bank Technical Paper 496 (2001) | G24: Source: World Bank TP 496, p.85 footnote (India standard single-lane rural road with 2cm bituminous + triple WBM + gravel layer) | H24: 2001
A25: 7 | B25: Rural Roads (China) | C25: 6600 | D25: 79000 | E25: =IFERROR(ROUND((C25+D25)/2,0),"") -> 42800 | F25: https://fsi-live.s3.us-west-1.amazonaws.com/s3fs-public/wong-et-al-2013-providing_quality_infrastructure.pdf | H25: 2007
A26: 8 | B26: General global estimate from research | C26: 10000 | D26: 15000 | E26: =IFERROR(ROUND((C26+D26)/2,0),"") -> 12500 | F26: https://assets.publishing.service.gov.uk/media/57a08bd7e5274a27b2000dc3/TI_UP_HD_Feb2007_Cost_of_Roads_in_Africa.pdf
B27: BLENDED AVERAGE (Min / Max / Mid) | C27: =IFERROR(ROUND(AVERAGE(C19:C26),0),"") -> 88073 | D27: =IFERROR(ROUND(AVERAGE(D19:D26),0),"") -> 156410 | E27: =IFERROR(ROUND(AVERAGE(E19:E26),0),"") -> 122241
A29: Rural Road Bridge (vehicular, simple) (per LF of deck)
A30: # | B30: Geography / Context | C30: Low Est. (USD) | D30: High Est. (USD) | E30: Source Mid | F30: Source Name | G30: Full Citation | H30: Year
A31: 1 | B31: Global (Evercross 2024 — beam bridges, material + construction) | C31: 400 | D31: 1600 | E31: =IFERROR(ROUND((C31+D31)/2,0),"") -> 1000 | F31: Evercross Bridge, How Much Does It Cost To Build A Pedestrian Bridge? (2024) | G31: Source: Evercross Bridge / Bailey Bridge Solution, How Much Does It Cost To Build A Pedestrian Bridge?, 2024-12-16 (beam bridges $400-$1,600/LF; applied here as simple vehicular beam bridge analogue) | H31: 2024
A32: 2 | B32: India (WB TP 496 — major cross-drainage structure, per m of span, 2001 USD) | C32: 1143 | D32: 1143 | E32: =IFERROR(ROUND((C32+D32)/2,0),"") -> 1143 | F32: World Bank Technical Paper 496 (2001) | G32: Source: World Bank TP 496, Table E.1.3, Major CD $3,750/m financial capital cost converted to $/LF ($3,750 / 3.28 ft/m) | H32: 2001
A33: 3 | B33: US: single-lane rural bridge 20ft -24ft wide x 40 ft span | C33: 7600 | D33: 9200 | E33: =IFERROR(ROUND((C33+D33)/2,0),"") -> 8400 | F33: https://www.fhwa.dot.gov/bridge/nbi/sd2024.cfm | G33: Source: US D.O.T. FHA | H33: 2024 | I33: 20 ft (single lane, standard rural) $383/ft^2 = $7660/LF 24 ft = $9200/LF
B34: BLENDED AVERAGE (Min / Max / Mid) | C34: =IFERROR(ROUND(AVERAGE(C31:C33),0),"") -> 3048 | D34: =IFERROR(ROUND(AVERAGE(D31:D33),0),"") -> 3981 | E34: =IFERROR(ROUND((C34+D34)/2,0),"") -> 3515
A36: Fixed Culvert Crossing (per LF, installed)
A37: # | B37: Geography / Context | C37: Low Est. (USD) | D37: High Est. (USD) | E37: Source Mid | F37: Source Name | G37: Full Citation | H37: Year
A38: 1 | B38: USA (Fairfax County VA — 4'x4' single box culvert) | C38: 533 | D38: 533 | E38: =IFERROR(ROUND((C38+D38)/2,0),"") -> 533 | F38: Fairfax County FY2026 Unit Price Schedule | G38: Source: Fairfax County Public Works, Unit Price Schedule, FY2026 (Feb 2026), Storm Sewer — Culverts, Single Box Culvert 4'x4' | H38: 2026
A39: 2 | B39: USA (Fairfax County VA — 8'x8' to 12'x8' box culvert) | C39: 1092 | D39: 1703 | E39: =IFERROR(ROUND((C39+D39)/2,0),"") -> 1398 | F39: Fairfax County FY2026 Unit Price Schedule | G39: Source: Fairfax County Public Works, Unit Price Schedule, FY2026 (Feb 2026), Single/Oversized Box Culvert 8'x8' to 12'x8' | H39: 2026
A40: 3 | B40: Kenya (Lower Eastern — 900mm pipe culvert, with/without surround, installed) | C40: 58 | D40: 151 | E40: =IFERROR(ROUND((C40+D40)/2,0),"") -> 105 | F40: Kenya Cost Estimation Manual 2025 (Lower Eastern) | G40: Source: Republic of Kenya, Cost Estimation Manual for Road Construction and Maintenance Works 2025 — Lower Eastern Region, Items 08.60.026/027 (900mm pipe culvert), KES 5,719-19,673/m converted at 130 KES/USD and 3.28 ft/m | H40: 2025
A41: 4 | B41: Kenya (Lower Eastern — 1200mm pipe culvert, with/without surround, installed) | C41: 105 | D41: 256 | E41: =IFERROR(ROUND((C41+D41)/2,0),"") -> 181 | F41: Kenya Cost Estimation Manual 2025 (Lower Eastern) | G41: Source: Republic of Kenya, Cost Estimation Manual 2025 — Lower Eastern Region, Items 08.60.028/029 (1200mm pipe culvert), KES 10,356-33,284/m converted | H41: 2025
A42: 5 | B42: USA (Pennsylvania DGLVR — 24"-36" HDPE pipe culvert, installed) | C42: 50 | D42: 80 | E42: =IFERROR(ROUND((C42+D42)/2,0),"") -> 65 | F42: Pennsylvania DGLVR Program Typical Costs 2015 | G42: Source: Penn State Center for Dirt and Gravel Road Studies, DGLVR Program Summary of Typical Costs, April 2015, Drainage section — 24"-36" HDPE dual-wall smooth bore | H42: 2015
B43: BLENDED AVERAGE (Min / Max / Mid) | C43: =IFERROR(ROUND(AVERAGE(C38:C42),0),"") -> 368 | D43: =IFERROR(ROUND(AVERAGE(D38:D42),0),"") -> 545 | E43: =IFERROR(ROUND((C43+D43)/2,0),"") -> 457
A45: Seasonal Causeway / Low-Water Crossing (per crossing)
...

Sheet Info for CamYoudahe
A1: CORRIDOR ADD-ON CALCULATOR — RNTI BUDGET PLANNING TOOL
B3: PURPOSE
B4: This tool helps rural transport planners estimate what Rural Networked Transport Infrastructure (RNTI)
B5: investments could be funded by allocating a small percentage of a larger corridor-level transport budget.
B6: It is intended as a conversation starter — not a final costing tool.
B8: HOW TO USE
B9: 1. Go to the 'Budget Calculator' sheet.
B10: 2. Enter your total corridor project budget (USD) in the yellow input cell.
B11: 3. Enter the percentage of that budget to allocate to RNTI (e.g., 1%, 5%, 10%).
B12: 4. Optionally adjust the maintenance reserve percentage.
B13: 5. In the Infrastructure Mix table, enter a quantity next to any RNTI type you want to fund.
B14: 6. The tool auto-calculates total costs, remaining budget, and a summary at the bottom.
B16: COLOR CODING
... B53: AfDB (2014). Study on Road Infrastructure Costs: Analysis of Unit Costs and Cost Overruns.

Sheet RNTI Components
A1: TABLE 1: RNTI COMPONENTS (Segerberg & Noriega, 2026)
B2: Source: Sustainability 2026, 18, 2842. https://doi.org/10.3390/su18062842
B4: Link Order | C4: Order 3 Tertiary Links (Road Dominant) | D4: Sub-Tertiary Links (Paths, Trails, Crossings)
B5: Corridor Level | C5: Inter-/intra-district; connects clusters of villages and local centers to all-weather roads and higher-order networks. In riverine contexts, connectivity may also be provided by water-based connectors. | D5: Hyperlocal; connects dispersed households, farms, and hamlets to the nearest tertiary link or community connector.
B6: Primary Function | C6: Facilitates movement of goods and people between villages, agricultural zones, markets, and service hubs. | D6: Provides first-/last-mile access by connecting households and farms to tertiary links and nearby services.
B7: Typical Users | C7: Local residents; smallholder and commercial farmers; informal transport operators. | D7: Rural households; school children; pedestrians; subsistence farmers; informal transporters.
B8: Typical Transport Modes | C8: Mixed traffic, including light motorized vehicles (e.g., small trucks, tricycles, motorcycles), IMTs (e.g., animal-drawn carts, bicycles, rickshaws). | D8: Predominantly NMT (walking, bicycles, livestock, handcarts). In riverine contexts, may include indigenous watercrafts and small motorized modes.
B9: Types of Infrastructure Links | C9: LVRs: unpaved rural roads, tracks suitable for IMT. Informal/ghost roads. Engineered bridges & fixed crossings. Seasonal causeways/low-water crossings. Temporary/emergency links. | D9: Low-capacity paths, trails, tracks. Improvised crossings (log, plank, bamboo bridges). Engineered trail bridges (cable trail bridges). Non-fixed crossings (ferries, canoes). Vertical/non-standard links (ladders, ropeways).
B10: Emerging Access (Non-link) | C10: N/A | D10: Drones and UAVs via aerial routes and associated support infrastructure.
B11: Engineering & Formality | C11: Generally engineered or semi-engineered; formally planned and maintained through district/national agencies. | D11: Predominantly non-engineered and informally developed by communities; some types may be formally built.
B12: Ancillary & Safety Infrastructure | C12: Drainage, signage/reflectors, waiting shelters, embankments, safety features. Context-dependent: lighting, ICT, charging points. | D12: Drainage at crossings, wayfinding/signage, benches/rest points, informal repair services. Emerging: ICT, charging points, rest stops.
B14: IMT = Intermediate Modes of Transport; LVR = Low-Volume Road; ICT = Information & Communication Technology; NMT = Non-Motorized Transport; UAV = Unmanned Aerial Vehicle
